<?xml version="1.0" ?>
<!-- =================================================================================== -->
<!-- |    This document was autogenerated by xacro .xacro | -->
<!-- |    EDITING THIS FILE BY HAND IS NOT RECOMMENDED                                 | -->
<!-- =================================================================================== -->
<robot name="suboto">
  <material name="aluminum">
    <color rgba="0.5 0.5 0.5 1"/>
  </material>
  <material name="plastic">
    <color rgba="0.1 0.1 0.1 1"/>
  </material>
  <link name="base_link"/>
  <link name="trunk_link">
    <inertial>
      <origin rpy="0 0 0" xyz="0.227000000000003 0 0"/>
      <mass value="50"/>
      <inertia ixx="2.0104166666666665" ixy="0" ixz="0" iyy="2.552083333333333" iyz="0" izz="3.541666666666666"/>
    </inertial>
    <visual>
      <origin rpy="0 0 0" xyz="0 0 0"/>
      <geometry>
        <mesh filename="package://cr100_description/meshes/trunk_link.STL"/>
      </geometry>
      <material name="">
        <color rgba="0.752941176470588 0.752941176470588 0.752941176470588 1"/>
      </material>
    </visual>
    <collision>
      <origin rpy="0 0 0" xyz="0 0 0"/>
      <geometry>
        <mesh filename="package://cr100_description/meshes/trunk_link.STL"/>
        <!-- <mesh filename="package://cr100_description/meshes/trunk_link_collision.STL" /> -->
        <!-- <box size="0.6 0.6 0.4"/> -->
      </geometry>
    </collision>
  </link>
  <joint name="trunk_joint" type="fixed">
    <origin rpy="0 0 0" xyz="-0.227000000000003 0 0.163000000000006"/>
    <parent link="base_link"/>
    <child link="trunk_link"/>
    <axis xyz="0 0 0"/>
  </joint>
  <link name="wheel_LF_link">
    <inertial>
      <origin rpy="0 0 0" xyz="0 0 0"/>
      <mass value="5"/>
      <inertia ixx="0.010534999999999997" ixy="0" ixz="0" iyy="0.010534999999999997" iyz="0" izz="0.016"/>
    </inertial>
    <visual>
      <origin rpy="0 0 0" xyz="0 0 0"/>
      <geometry>
        <mesh filename="package://cr100_description/meshes/wheel_LF_link.STL"/>
      </geometry>
      <material name="">
        <color rgba="0.941176470588235 0.674509803921569 0.117647058823529 1"/>
      </material>
    </visual>
    <collision>
      <origin rpy="1.5707963267948966 0 0" xyz="0 0 0"/>
      <geometry>
        <cylinder length="0.078" radius="0.08"/>
      </geometry>
    </collision>
  </link>
  <joint name="wheel_LF_joint" type="continuous">
    <parent link="base_link"/>
    <child link="wheel_LF_link"/>
    <origin rpy="0 0 0" xyz="0.0 0.230499999999998 0.0"/>
    <axis rpy="0 0 0" xyz="0 1 0"/>
  </joint>
  <link name="wheel_RF_link">
    <inertial>
      <origin rpy="0 0 0" xyz="0 0 0"/>
      <mass value="5"/>
      <inertia ixx="0.010534999999999997" ixy="0" ixz="0" iyy="0.010534999999999997" iyz="0" izz="0.016"/>
    </inertial>
    <visual>
      <origin rpy="3.141592653589793 0 0" xyz="0 0 0"/>
      <geometry>
        <mesh filename="package://cr100_description/meshes/wheel_LF_link.STL"/>
      </geometry>
      <material name="">
        <color rgba="0.941176470588235 0.674509803921569 0.117647058823529 1"/>
      </material>
    </visual>
    <collision>
      <origin rpy="1.5707963267948966 0 0" xyz="0 0 0"/>
      <geometry>
        <cylinder length="0.078" radius="0.08"/>
      </geometry>
    </collision>
  </link>
  <joint name="wheel_RF_joint" type="continuous">
    <parent link="base_link"/>
    <child link="wheel_RF_link"/>
    <origin rpy="0 0 0" xyz="0.0 -0.230499999999998 0.0"/>
    <axis rpy="0 0 0" xyz="0 1 0"/>
  </joint>
  <link name="caster_LB_link">
    <inertial>
      <origin rpy="0 0 0" xyz="0 0 0"/>
      <mass value="5"/>
      <inertia ixx="0.0028125" ixy="0" ixz="0" iyy="0.0028125" iyz="0" izz="0.0028125"/>
    </inertial>
    <visual>
      <origin rpy="0 0 0" xyz="0 0 0"/>
      <geometry>
        <mesh filename="package://cr100_description/meshes/caster_LB_link.STL"/>
      </geometry>
      <material name="">
        <color rgba="0.941176470588235 0.674509803921569 0.117647058823529 1"/>
      </material>
    </visual>
    <collision>
      <origin rpy="1.5707963267948966 0 0" xyz="0 0 0"/>
      <geometry>
        <cylinder length="0.078" radius="0.0375"/>
      </geometry>
    </collision>
  </link>
  <joint name="caster_LB_joint" type="continuous">
    <parent link="base_link"/>
    <child link="caster_LB_link"/>
    <dynamics damping="0.0"/>
    <!-- 必须为零 -->
    <limit effort="0.01" velocity="100"/>
    <origin rpy="0 0 0" xyz="-0.436000000000004 0.179999999999997 -0.0425000000000016"/>
    <axis rpy="0 0 0" xyz="0 1 0"/>
  </joint>
  <link name="caster_RB_link">
    <inertial>
      <origin rpy="0 0 0" xyz="0 0 0"/>
      <mass value="5"/>
      <inertia ixx="0.0028125" ixy="0" ixz="0" iyy="0.0028125" iyz="0" izz="0.0028125"/>
    </inertial>
    <visual>
      <origin rpy="3.141592653589793 0 0" xyz="0 0 0"/>
      <geometry>
        <mesh filename="package://cr100_description/meshes/caster_LB_link.STL"/>
      </geometry>
      <material name="">
        <color rgba="0.941176470588235 0.674509803921569 0.117647058823529 1"/>
      </material>
    </visual>
    <collision>
      <origin rpy="1.5707963267948966 0 0" xyz="0 0 0"/>
      <geometry>
        <cylinder length="0.078" radius="0.0375"/>
      </geometry>
    </collision>
  </link>
  <joint name="caster_RB_joint" type="continuous">
    <parent link="base_link"/>
    <child link="caster_RB_link"/>
    <dynamics damping="0.0"/>
    <!-- 必须为零 -->
    <limit effort="0.01" velocity="100"/>
    <origin rpy="0 0 0" xyz="-0.436000000000004 -0.179999999999997 -0.0425000000000016"/>
    <axis rpy="0 0 0" xyz="0 1 0"/>
  </joint>
  <link name="laser_F_link">
    <inertial>
      <origin rpy="0 0 0" xyz="0 0 0"/>
      <mass value="0"/>
      <inertia ixx="0" ixy="0" ixz="0" iyy="0" iyz="0" izz="0"/>
    </inertial>
    <visual>
      <origin rpy="0 0 0" xyz="0 0 0"/>
      <geometry>
        <mesh filename="package://cr100_description/meshes/laser_F_link.STL"/>
      </geometry>
      <material name="">
        <color rgba="0.941176470588235 0.674509803921569 0.117647058823529 1"/>
      </material>
    </visual>
    <collision>
      <origin rpy="0 0 0" xyz="0 0 0"/>
      <geometry>
        <mesh filename="package://cr100_description/meshes/laser_F_link.STL"/>
      </geometry>
    </collision>
  </link>
  <joint name="laser_F_joint" type="fixed">
    <origin rpy="0 0 -0.028" xyz="-0.05 -0.005 0.3945009"/>
    <parent link="base_link"/>
    <child link="laser_F_link"/>
    <axis xyz="0 0 0"/>
  </joint>
  <!-- <xacro:laser laser_prefix="laser_B" sim_gazebo="$(arg sim_gazebo)">
            <origin rpy="-3.14159265358978 0 -3.14159265358979"
                xyz="-0.519999999999984 0 -0.0213199999999936" />
        </xacro:laser> -->
  <link name="lidar_link">
    <inertial>
      <origin rpy="0 0 0" xyz="0 0 0"/>
      <mass value="0"/>
      <inertia ixx="0" ixy="0" ixz="0" iyy="0" iyz="0" izz="0"/>
    </inertial>
    <visual>
      <origin rpy="0 0 0" xyz="0 0 0"/>
      <geometry>
        <mesh filename="package://cr100_description/meshes/lidar_link.STL"/>
      </geometry>
      <material name="">
        <color rgba="0.792156862745098 0.819607843137255 0.933333333333333 1"/>
      </material>
    </visual>
    <collision>
      <origin rpy="0 0 0" xyz="0 0 0"/>
      <geometry>
        <mesh filename="package://cr100_description/meshes/lidar_link.STL"/>
      </geometry>
    </collision>
  </link>
  <joint name="lidar_joint" type="fixed">
    <origin rpy="0.0 0.0 0.0" xyz="0.0660000000000008 0.0 0.3445009"/>
    <parent link="base_link"/>
    <child link="lidar_link"/>
  </joint>
  <link name="livox_frame"/>
  <joint name="lidar_imu_joint" type="fixed">
    <parent link="lidar_link"/>
    <child link="livox_frame"/>
    <origin rpy="0 0 0" xyz="-0.011 -0.02329 0.04412"/>
  </joint>
  <link name="laser_B_link">
    <inertial>
      <origin rpy="0 0 0" xyz="0 0 0"/>
      <mass value="0"/>
      <inertia ixx="0" ixy="0" ixz="0" iyy="0" iyz="0" izz="0"/>
    </inertial>
    <visual>
      <origin rpy="0 0 0" xyz="0 0 0"/>
      <geometry>
        <mesh filename="package://cr100_description/meshes/laser_F_link.STL"/>
      </geometry>
      <material name="">
        <color rgba="0.941176470588235 0.674509803921569 0.117647058823529 1"/>
      </material>
    </visual>
    <collision>
      <origin rpy="0 0 0" xyz="0 0 0"/>
      <geometry>
        <mesh filename="package://cr100_description/meshes/laser_F_link.STL"/>
      </geometry>
    </collision>
  </link>
  <joint name="laser_B_joint" type="fixed">
    <origin rpy="0.0 0.0 3.14159265358979" xyz="-0.4 0.0 0.3445009"/>
    <parent link="base_link"/>
    <child link="laser_B_link"/>
    <axis xyz="0 0 0"/>
  </joint>
  <!-- <xacro:sensor_d435i name="front_camera" parent="base_link" use_nominal_extrinsics="true">
            <origin xyz="0.10615 0 0.25" rpy="0 0 0" />
        </xacro:sensor_d435i> -->
</robot>
